import Conversation from "../models/conversation.model.js";
import Message from "../models/message.model.js";

export const sendMessage = async (req, res) => {
  try {
    const { message } = req.body;
    const { id: receiverId } = req.params;
    const senderId = req.user._id;

    let conversation = await Conversation.findOne({
      participants: { $all: [senderId, receiverId] },
    });

    if (!conversation) {
      conversation = await Conversation.create({
        participants: [senderId, receiverId],
      });
    }

    const newMessage = new Message({
      senderId,
      receiverId,
      message,
    });

    if (newMessage) {
      conversation.messages.push(newMessage._id);
    }
    // This will run in parallel
    await Promise.all([newMessage.save(), conversation.save()]);
    console.log(newMessage);
    res.status(200).json(newMessage);
  } catch (error) {
    console.log("Error in sendMessage controller", error.message);
    res.status(500).json({ error: "Internal server error" });
  }
};

export const getMessage = async (req, res) => {
  try {
    const { id: userToChatId } = req.params;
    const senderId = req.user._id;

    let conversation = await Conversation.findOne({
      participants: { $all: [senderId, userToChatId] },
    }).populate("messages"); // Not a error but the message object itself

    if (!conversation) {
      return res.status(200).json({ error: "Conversation not started yet" });
    }
    const messages = conversation.messages;

    res.status(200).json(messages);
  } catch (error) {
    console.log("Error in getMessage controller", error.message);
    res.status(500).json({ error: "Internal server error" });
  }
};
